<robot name="HU_D04_01">

  


  <link name="base_link">
    <inertial>
      <origin xyz="0.002916 -8E-06 0.041359" rpy="0 0 0" />
      <mass value="5.904962" />
      <inertia ixx="0.038209" ixy="4E-06" ixz="0.001989" iyy="0.013916" iyz="-8E-06" izz="0.040472" />
    </inertial>
    <visual>
      <origin xyz="0 0 0" rpy="0 0 0" />
      <geometry>
        <mesh filename="package://HU_D04_description/meshes/HU_D04_01/base_link.STL" />
      </geometry>
      <material name="">
        <color rgba="0.75294 0.75294 0.75294 1" />
      </material>
    </visual>
    
  <collision><origin xyz="0 0 -0.08" rpy="0 0 0" /><geometry><sphere radius="0.07" /></geometry></collision></link>
  <link name="left_hip_pitch_link">
    <inertial>
      <origin xyz="0.0019 0.001536 -0.086008" rpy="0 0 0" />
      <mass value="2.255011" />
      <inertia ixx="0.003233" ixy="2E-06" ixz="-1.3E-05" iyy="0.003816" iyz="3.5E-05" izz="0.002888" />
    </inertial>
    <visual>
      <origin xyz="0 0 0" rpy="0 0 0" />
      <geometry>
        <mesh filename="package://HU_D04_description/meshes/HU_D04_01/left_hip_pitch_link.STL" />
      </geometry>
      <material name="">
        <color rgba="0.75294 0.75294 0.75294 1" />
      </material>
    </visual>
    
  </link>
  <joint name="left_hip_pitch_joint" type="revolute">
    <origin xyz="0.017007 0.1283 0.0081917" rpy="0 0 0" />
    <parent link="base_link" />
    <child link="left_hip_pitch_link" />
    <axis xyz="0 0.90631 -0.42262" />
    <limit lower="-2.618" upper="2.618" effort="140" velocity="5" />
  </joint>
  <link name="left_hip_roll_link">
    <inertial>
      <origin xyz="0.00075 1E-05 -0.118609" rpy="0 0 0" />
      <mass value="2.121806" />
      <inertia ixx="0.004035" ixy="3E-06" ixz="-0.000137" iyy="0.004267" iyz="1E-06" izz="0.002342" />
    </inertial>
    <visual>
      <origin xyz="0 0 0" rpy="0 0 0" />
      <geometry>
        <mesh filename="package://HU_D04_description/meshes/HU_D04_01/left_hip_roll_link.STL" />
      </geometry>
      <material name="">
        <color rgba="0.75294 0.75294 0.75294 1" />
      </material>
    </visual>
    
  <collision><origin xyz="0.02 0 -0.05" rpy="0 0 0" /><geometry><sphere radius="0.05" /></geometry></collision></link>
  <joint name="left_hip_roll_joint" type="revolute">
    <origin xyz="-0.01 0.0016596 -0.0920417" rpy="0 0 0" />
    <parent link="left_hip_pitch_link" />
    <child link="left_hip_roll_link" />
    <axis xyz="1 0 0" />
    <limit lower="-0.8727" upper="2.094" effort="140" velocity="5" />
  </joint>
  <link name="left_hip_yaw_link">
    <inertial>
      <origin xyz="0.006364 0.000963 -0.143266" rpy="0 0 0" />
      <mass value="2.994098" />
      <inertia ixx="0.024104" ixy="9E-06" ixz="-0.001176" iyy="0.024609" iyz="0.000111" izz="0.004856" />
    </inertial>
    <visual>
      <origin xyz="0 0 0" rpy="0 0 0" />
      <geometry>
        <mesh filename="package://HU_D04_description/meshes/HU_D04_01/left_hip_yaw_link.STL" />
      </geometry>
      <material name="">
        <color rgba="0.75294 0.75294 0.75294 1" />
      </material>
    </visual>
    
  </link>
  <joint name="left_hip_yaw_joint" type="revolute">
    <origin xyz="0 0 -0.1774" rpy="0 0 0" />
    <parent link="left_hip_roll_link" />
    <child link="left_hip_yaw_link" />
    <axis xyz="0 0 1" />
    <limit lower="-2.618" upper="2.618" effort="140" velocity="5" />
  </joint>
  <link name="left_knee_link">
    <inertial>
      <origin xyz="0.008034 0.005502 -0.139341" rpy="0 0 0" />
      <mass value="3.004275" />
      <inertia ixx="0.026945" ixy="9.1E-05" ixz="8.3E-05" iyy="0.026541" iyz="-0.00215" izz="0.003135" />
    </inertial>
    <visual>
      <origin xyz="0 0 0" rpy="0 0 0" />
      <geometry>
        <mesh filename="package://HU_D04_description/meshes/HU_D04_01/left_knee_link.STL" />
      </geometry>
      <material name="">
        <color rgba="0.75294 0.75294 0.75294 1" />
      </material>
    </visual>
    
  <collision><origin xyz="0.02 0 -0.05" rpy="0 0 0" /><geometry><sphere radius="0.05" /></geometry></collision></link>
  <joint name="left_knee_joint" type="revolute">
    <origin xyz="0 0 -0.1976" rpy="0 0 0" />
    <parent link="left_hip_yaw_link" />
    <child link="left_knee_link" />
    <axis xyz="0 1 0" />
    <limit lower="-0.087" upper="2.583" effort="140" velocity="5" />
  </joint>
  <link name="left_ankle_pitch_link">
    <inertial>
      <origin xyz="0 0 0.001077" rpy="0 0 0" />
      <mass value="0.042944" />
      <inertia ixx="4E-06" ixy="0" ixz="0" iyy="2E-06" iyz="0" izz="4E-06" />
    </inertial>
    <visual>
      <origin xyz="0 0 0" rpy="0 0 0" />
      <geometry>
        <mesh filename="package://HU_D04_description/meshes/HU_D04_01/left_ankle_pitch_link.STL" />
      </geometry>
      <material name="">
        <color rgba="0.75294 0.75294 0.75294 1" />
      </material>
    </visual>
    
  </link>
  <joint name="left_ankle_pitch_joint" type="revolute">
    <origin xyz="0 0 -0.385" rpy="0 0 0" />
    <parent link="left_knee_link" />
    <child link="left_ankle_pitch_link" />
    <axis xyz="0 1 0" />
    <limit lower="-1.012" upper="0.611" effort="42" velocity="13.6" />
  </joint>
  <link name="left_ankle_roll_link">
    <inertial>
      <origin xyz="0.009720 0 -0.035233" rpy="0 0 0" />
      <mass value="1.206425" />
      <inertia ixx="0.000924" ixy="0" ixz="0.000471" iyy="0.004760" iyz="0" izz="0.004924" />
    </inertial>
    <visual>
      <origin xyz="0 0 0" rpy="0 0 0" />
      <geometry>
        <mesh filename="package://HU_D04_description/meshes/HU_D04_01/left_ankle_roll_link.STL" />
      </geometry>
      <material name="">
        <color rgba="0.75294 0.75294 0.75294 1" />
      </material>
    </visual>
    <collision>
      <origin rpy="0 0 0" xyz="0.018 0 -0.0535" />
      <geometry>
        <box size="0.25 0.094 0.02" />
      </geometry>
    </collision>
    
  <collision><origin xyz="0.018 0 -0.0535" rpy="0 0 0" /><geometry><box size="0.25 0.094 0.02" /></geometry></collision></link>
  <joint name="left_ankle_roll_joint" type="revolute">
    <origin xyz="0 0 0" rpy="0 0 0" />
    <parent link="left_ankle_pitch_link" />
    <child link="left_ankle_roll_link" />
    <axis xyz="1 0 0" />
    <limit lower="-0.436" upper="0.436" effort="42" velocity="13.6" />
  </joint>

  
  <joint name="contact_foot_center_joint_L" type="fixed">
    <origin xyz="0.0 0 -0.0625" rpy="0 0 0" />
    <parent link="left_ankle_roll_link" />
    <child link="contact_foot_center_L" />
  </joint>
  <link name="contact_foot_center_L">
    <inertial>
      <origin xyz=".0 .0 .0" rpy="0 0 0" />
      <mass value="0.001" />
      <inertia ixx="0.0000001" ixy="0.0" ixz="0.0" iyy="0.0000001" iyz="0.0" izz="0.0000001" />
    </inertial>
    <visual>
      <origin xyz="0 0 0" rpy="0 0 0" />
      <geometry>
        <box size="0.01 0.01 0.01" />
      </geometry>
      <material name="">
        <color rgba="1 0 0 1" />
      </material>
    </visual>
  </link>

  <joint name="contact_foot_heel_joint_L" type="fixed">
    <origin xyz="-0.106 0 -0.0625" rpy="0 0 0" />
    <parent link="left_ankle_roll_link" />
    <child link="contact_foot_heel_L" />
  </joint>
  <link name="contact_foot_heel_L">
    <inertial>
      <origin xyz=".0 .0 .0" rpy="0 0 0" />
      <mass value="0.001" />
      <inertia ixx="0.0000001" ixy="0.0" ixz="0.0" iyy="0.0000001" iyz="0.0" izz="0.0000001" />
    </inertial>
    <visual>
      <origin xyz="0 0 0" rpy="0 0 0" />
      <geometry>
        <box size="0.01 0.01 0.01" />
      </geometry>
      <material name="">
        <color rgba="1 0 0 1" />
      </material>
    </visual>
  </link>

  <joint name="contact_foot_tip_joint_L" type="fixed">
    <origin xyz="0.154 0 -0.0625" rpy="0 0 0" />
    <parent link="left_ankle_roll_link" />
    <child link="contact_foot_tip_L" />
  </joint>
  <link name="contact_foot_tip_L">
    <inertial>
      <origin xyz=".0 .0 .0" rpy="0 0 0" />
      <mass value="0.001" />
      <inertia ixx="0.0000001" ixy="0.0" ixz="0.0" iyy="0.0000001" iyz="0.0" izz="0.0000001" />
    </inertial>
    <visual>
      <origin xyz="0 0 0" rpy="0 0 0" />
      <geometry>
        <box size="0.01 0.01 0.01" />
      </geometry>
      <material name="">
        <color rgba="1 0 0 1" />
      </material>
    </visual>
  </link>

  <link name="right_hip_pitch_link">
    <inertial>
      <origin xyz="0.0019 -0.001536 -0.086008" rpy="0 0 0" />
      <mass value="2.253993" />
      <inertia ixx="0.003231" ixy="-1.8E-05" ixz="-1.2E-05" iyy="0.003814" iyz="-2E-06" izz="0.002888" />
    </inertial>
    <visual>
      <origin xyz="0 0 0" rpy="0 0 0" />
      <geometry>
        <mesh filename="package://HU_D04_description/meshes/HU_D04_01/right_hip_pitch_link.STL" />
      </geometry>
      <material name="">
        <color rgba="0.75294 0.75294 0.75294 1" />
      </material>
    </visual>
    
  </link>
  <joint name="right_hip_pitch_joint" type="revolute">
    <origin xyz="0.017007 -0.1283 0.0081917" rpy="0 0 0" />
    <parent link="base_link" />
    <child link="right_hip_pitch_link" />
    <axis xyz="0 0.90631 0.42262" />
    <limit lower="-2.618" upper="2.618" effort="140" velocity="5" />
  </joint>
  <link name="right_hip_roll_link">
    <inertial>
      <origin xyz="0.000764 1E-05 -0.118627" rpy="0 0 0" />
      <mass value="2.121322" />
      <inertia ixx="0.004031" ixy="3E-06" ixz="-0.000139" iyy="0.004262" iyz="1E-06" izz="0.00234" />
    </inertial>
    <visual>
      <origin xyz="0 0 0" rpy="0 0 0" />
      <geometry>
        <mesh filename="package://HU_D04_description/meshes/HU_D04_01/right_hip_roll_link.STL" />
      </geometry>
      <material name="">
        <color rgba="0.75294 0.75294 0.75294 1" />
      </material>
    </visual>
    
  <collision><origin xyz="0.02 0 -0.05" rpy="0 0 0" /><geometry><sphere radius="0.05" /></geometry></collision></link>
  <joint name="right_hip_roll_joint" type="revolute">
    <origin xyz="-0.01 -0.0016596 -0.0920417" rpy="0 0 0" />
    <parent link="right_hip_pitch_link" />
    <child link="right_hip_roll_link" />
    <axis xyz="1 0 0" />
    <limit lower="-2.094" upper="0.8727" effort="140" velocity="5" />
  </joint>
  <link name="right_hip_yaw_link">
    <inertial>
      <origin xyz="0.006367 -0.000835 -0.143269" rpy="0 0 0" />
      <mass value="2.994098" />
      <inertia ixx="0.024106" ixy="-8E-06" ixz="-0.001175" iyy="0.02461" iyz="-0.000165" izz="0.004856" />
    </inertial>
    <visual>
      <origin xyz="0 0 0" rpy="0 0 0" />
      <geometry>
        <mesh filename="package://HU_D04_description/meshes/HU_D04_01/right_hip_yaw_link.STL" />
      </geometry>
      <material name="">
        <color rgba="0.75294 0.75294 0.75294 1" />
      </material>
    </visual>
    
  </link>
  <joint name="right_hip_yaw_joint" type="revolute">
    <origin xyz="0 0 -0.1774" rpy="0 0 0" />
    <parent link="right_hip_roll_link" />
    <child link="right_hip_yaw_link" />
    <axis xyz="0 0 1" />
    <limit lower="-2.618" upper="2.618" effort="140" velocity="5" />
  </joint>
  <link name="right_knee_link">
    <inertial>
      <origin xyz="0.007541 -0.00542 -0.140219" rpy="0 0 0" />
      <mass value="2.944928" />
      <inertia ixx="0.026634" ixy="-9.1E-05" ixz="0.000115" iyy="0.026187" iyz="0.002135" izz="0.00303" />
    </inertial>
    <visual>
      <origin xyz="0 0 0" rpy="0 0 0" />
      <geometry>
        <mesh filename="package://HU_D04_description/meshes/HU_D04_01/right_knee_link.STL" />
      </geometry>
      <material name="">
        <color rgba="0.75294 0.75294 0.75294 1" />
      </material>
    </visual>
    
  <collision><origin xyz="0.02 0 -0.05" rpy="0 0 0" /><geometry><sphere radius="0.05" /></geometry></collision></link>
  <joint name="right_knee_joint" type="revolute">
    <origin xyz="0 0 -0.1976" rpy="0 0 0" />
    <parent link="right_hip_yaw_link" />
    <child link="right_knee_link" />
    <axis xyz="0 1 0" />
    <limit lower="-0.087" upper="2.583" effort="140" velocity="5" />
  </joint>
  <link name="right_ankle_pitch_link">
    <inertial>
      <origin xyz="0 0 0.001077" rpy="0 0 0" />
      <mass value="0.042944" />
      <inertia ixx="4E-06" ixy="0" ixz="0" iyy="2E-06" iyz="0" izz="4E-06" />
    </inertial>
    <visual>
      <origin xyz="0 0 0" rpy="0 0 0" />
      <geometry>
        <mesh filename="package://HU_D04_description/meshes/HU_D04_01/right_ankle_pitch_link.STL" />
      </geometry>
      <material name="">
        <color rgba="0.75294 0.75294 0.75294 1" />
      </material>
    </visual>
    
  </link>
  <joint name="right_ankle_pitch_joint" type="revolute">
    <origin xyz="0 0 -0.385" rpy="0 0 0" />
    <parent link="right_knee_link" />
    <child link="right_ankle_pitch_link" />
    <axis xyz="0 1 0" />
    <limit lower="-1.012" upper="0.611" effort="42" velocity="13.6" />
  </joint>
  <link name="right_ankle_roll_link">
    <inertial>
      <origin xyz="0.009720 0 -0.035233" rpy="0 0 0" />
      <mass value="1.206425" />
      <inertia ixx="0.000924" ixy="0" ixz="0.000471" iyy="0.004760" iyz="0" izz="0.004924" />
    </inertial>
    <visual>
      <origin xyz="0 0 0" rpy="0 0 0" />
      <geometry>
        <mesh filename="package://HU_D04_description/meshes/HU_D04_01/right_ankle_roll_link.STL" />
      </geometry>
      <material name="">
        <color rgba="0.75294 0.75294 0.75294 1" />
      </material>
    </visual>
    <collision>
      <origin rpy="0 0 0" xyz="0.018 0 -0.0535" />
      <geometry>
        <box size="0.25 0.094 0.02" />
      </geometry>
    </collision>
    
  <collision><origin xyz="0.018 0 -0.0535" rpy="0 0 0" /><geometry><box size="0.25 0.094 0.02" /></geometry></collision></link>
  <joint name="right_ankle_roll_joint" type="revolute">
    <origin xyz="0 0 0" rpy="0 0 0" />
    <parent link="right_ankle_pitch_link" />
    <child link="right_ankle_roll_link" />
    <axis xyz="1 0 0" />
    <limit lower="-0.436" upper="0.436" effort="42" velocity="13.6" />
  </joint>

  
  <joint name="contact_foot_center_joint_R" type="fixed">
    <origin xyz="0.0 0 -0.0625" rpy="0 0 0" />
    <parent link="right_ankle_roll_link" />
    <child link="contact_foot_center_R" />
  </joint>
  <link name="contact_foot_center_R">
    <inertial>
      <origin xyz=".0 .0 .0" rpy="0 0 0" />
      <mass value="0.001" />
      <inertia ixx="0.0000001" ixy="0.0" ixz="0.0" iyy="0.0000001" iyz="0.0" izz="0.0000001" />
    </inertial>
    <visual>
      <origin xyz="0 0 0" rpy="0 0 0" />
      <geometry>
        <box size="0.01 0.01 0.01" />
      </geometry>
      <material name="">
        <color rgba="1 0 0 1" />
      </material>
    </visual>
  </link>

  <joint name="contact_foot_heel_joint_R" type="fixed">
    <origin xyz="-0.106 0 -0.0625" rpy="0 0 0" />
    <parent link="right_ankle_roll_link" />
    <child link="contact_foot_heel_R" />
  </joint>
  <link name="contact_foot_heel_R">
    <inertial>
      <origin xyz=".0 .0 .0" rpy="0 0 0" />
      <mass value="0.001" />
      <inertia ixx="0.0000001" ixy="0.0" ixz="0.0" iyy="0.0000001" iyz="0.0" izz="0.0000001" />
    </inertial>
    <visual>
      <origin xyz="0 0 0" rpy="0 0 0" />
      <geometry>
        <box size="0.01 0.01 0.01" />
      </geometry>
      <material name="">
        <color rgba="1 0 0 1" />
      </material>
    </visual>
  </link>

  <joint name="contact_foot_tip_joint_R" type="fixed">
    <origin xyz="0.154 0 -0.0625" rpy="0 0 0" />
    <parent link="right_ankle_roll_link" />
    <child link="contact_foot_tip_R" />
  </joint>
  <link name="contact_foot_tip_R">
    <inertial>
      <origin xyz=".0 .0 .0" rpy="0 0 0" />
      <mass value="0.001" />
      <inertia ixx="0.0000001" ixy="0.0" ixz="0.0" iyy="0.0000001" iyz="0.0" izz="0.0000001" />
    </inertial>
    <visual>
      <origin xyz="0 0 0" rpy="0 0 0" />
      <geometry>
        <box size="0.01 0.01 0.01" />
      </geometry>
      <material name="">
        <color rgba="1 0 0 1" />
      </material>
    </visual>
  </link>

  <link name="waist_yaw_link">
    <inertial>
      <origin xyz="0.019885 -0.000163 0.029632" rpy="0 0 0" />
      <mass value="0.654749" />
      <inertia ixx="0.000616" ixy="-5E-06" ixz="-2.1E-05" iyy="0.001108" iyz="1E-06" izz="0.001156" />
    </inertial>
    <visual>
      <origin xyz="0 0 0" rpy="0 0 0" />
      <geometry>
        <mesh filename="package://HU_D04_description/meshes/HU_D04_01/waist_yaw_link.STL" />
      </geometry>
      <material name="">
        <color rgba="0.75294 0.75294 0.75294 1" />
      </material>
    </visual>
    
  </link>
  <joint name="waist_yaw_joint" type="revolute">
    <origin xyz="0 0 0.10239" rpy="0 0 0" />
    <parent link="base_link" />
    <child link="waist_yaw_link" />
    <axis xyz="0 0 1" />
    <limit lower="-2.618" upper="2.618" effort="42" velocity="13.6" />
  </joint>
  <link name="waist_roll_link">
    <inertial>
      <origin xyz="0 0 -0.000149" rpy="0 0 0" />
      <mass value="0.291501" />
      <inertia ixx="0.00016" ixy="0" ixz="0" iyy="3.6E-05" iyz="0" izz="0.000164" />
    </inertial>
    <visual>
      <origin xyz="0 0 0" rpy="0 0 0" />
      <geometry>
        <mesh filename="package://HU_D04_description/meshes/HU_D04_01/waist_roll_link.STL" />
      </geometry>
      <material name="">
        <color rgba="0.75294 0.75294 0.75294 1" />
      </material>
    </visual>
    
  </link>
  <joint name="waist_roll_joint" type="revolute">
    <origin xyz="0 0 0.057" rpy="0 0 0" />
    <parent link="waist_yaw_link" />
    <child link="waist_roll_link" />
    <axis xyz="1 0 0" />
    <limit lower="-0.524" upper="0.524" effort="42" velocity="13.6" />
  </joint>
  <link name="waist_pitch_link">
    <inertial>
      <origin xyz="-0.006815 0.000038 0.196229" rpy="0 0 0" />
      <mass value="11.882244" />
      <inertia ixx="0.169231" ixy="0.000065" ixz="0.000953" iyy="0.136241" iyz="-0.000057" izz="0.104458" />
    </inertial>
    <visual>
      <origin xyz="0 0 0" rpy="0 0 0" />
      <geometry>
        <mesh filename="package://HU_D04_description/meshes/HU_D04_01/waist_pitch_link.STL" />
      </geometry>
      <material name="">
        <color rgba="0.75294 0.75294 0.75294 1" />
      </material>
    </visual>
    
  <collision><origin xyz="0 0 0.05" rpy="0 0 0" /><geometry><sphere radius="0.08" /></geometry></collision></link>
  <joint name="waist_pitch_joint" type="revolute">
    <origin xyz="0 0 0" rpy="0 0 0" />
    <parent link="waist_roll_link" />
    <child link="waist_pitch_link" />
    <axis xyz="0 1 0" />
    <limit lower="-0.524" upper="0.785" effort="42" velocity="13.6" />
  </joint>
  
  <link name="left_shoulder_pitch_link">
    <inertial>
      <origin xyz="0.003151 0.031104 -2.2E-05" rpy="0 0 0" />
      <mass value="0.244765" />
      <inertia ixx="0.000253" ixy="-2.3E-05" ixz="0" iyy="0.000367" iyz="0" izz="0.000429" />
    </inertial>
    <visual>
      <origin xyz="0 0 0" rpy="0 0 0" />
      <geometry>
        <mesh filename="package://HU_D04_description/meshes/HU_D04_01/left_shoulder_pitch_link.STL" />
      </geometry>
      <material name="">
        <color rgba="0.75294 0.75294 0.75294 1" />
      </material>
    </visual>
    
  </link>
  <joint name="left_shoulder_pitch_joint" type="revolute">
    <origin xyz="0 0.1589 0.2822" rpy="0 0 0" />
    <parent link="waist_pitch_link" />
    <child link="left_shoulder_pitch_link" />
    <axis xyz="0 1 0" />
    <limit lower="-2.792" upper="2.792" effort="42" velocity="19.6" />
  </joint>
  <link name="left_shoulder_roll_link">
    <inertial>
      <origin xyz="0.003525 8.8E-05 -0.046695" rpy="0 0 0" />
      <mass value="1.740745" />
      <inertia ixx="0.004948" ixy="0" ixz="-0.000258" iyy="0.004931" iyz="2E-06" izz="0.001384" />
    </inertial>
    <visual>
      <origin xyz="0 0 0" rpy="0 0 0" />
      <geometry>
        <mesh filename="package://HU_D04_description/meshes/HU_D04_01/left_shoulder_roll_link.STL" />
      </geometry>
      <material name="">
        <color rgba="0.75294 0.75294 0.75294 1" />
      </material>
    </visual>
    
  </link>
  <joint name="left_shoulder_roll_joint" type="revolute">
    <origin xyz="0 0.055 0" rpy="0 0 0" />
    <parent link="left_shoulder_pitch_link" />
    <child link="left_shoulder_roll_link" />
    <axis xyz="1 0 0" />
    <limit lower="-0.087" upper="3.229" effort="42" velocity="19.6" />
  </joint>
  <link name="left_shoulder_yaw_link">
    <inertial>
      <origin xyz="-0.010067 0.003571 -0.065207" rpy="0 0 0" />
      <mass value="0.307657" />
      <inertia ixx="0.000874" ixy="-8E-06" ixz="-1.9E-05" iyy="0.000738" iyz="3.4E-05" izz="0.000405" />
    </inertial>
    <visual>
      <origin xyz="0 0 0" rpy="0 0 0" />
      <geometry>
        <mesh filename="package://HU_D04_description/meshes/HU_D04_01/left_shoulder_yaw_link.STL" />
      </geometry>
      <material name="">
        <color rgba="0.75294 0.75294 0.75294 1" />
      </material>
    </visual>
    
  <collision><origin xyz="0 0 -0.015" rpy="0 0 0" /><geometry><sphere radius="0.03" /></geometry></collision></link>
  <joint name="left_shoulder_yaw_joint" type="revolute">
    <origin xyz="0 0 -0.1306" rpy="0 0 0" />
    <parent link="left_shoulder_roll_link" />
    <child link="left_shoulder_yaw_link" />
    <axis xyz="0 0 1" />
    <limit lower="-3.403" upper="1.571" effort="42" velocity="19.6" />
  </joint>
  <link name="left_elbow_link">
    <inertial>
      <origin xyz="0.000057 0.004497 -0.027441" rpy="0 0 0" />
      <mass value="1.275459" />
      <inertia ixx="0.002852" ixy="-0.000003" ixz="0.000017" iyy="0.002876" iyz="-0.000129" izz="0.000888" />
    </inertial>
    <visual>
      <origin xyz="0 0 0" rpy="0 0 0" />
      <geometry>
        <mesh filename="package://HU_D04_description/meshes/HU_D04_01/left_elbow_link.STL" />
      </geometry>
      <material name="">
        <color rgba="0.75294 0.75294 0.75294 1" />
      </material>
    </visual>
    
  <collision><origin xyz="0.05 0 -0.01" rpy="0 0 0" /><geometry><sphere radius="0.03" /></geometry></collision></link>
  <joint name="left_elbow_joint" type="revolute">
    <origin xyz="0 0 -0.1157" rpy="0 0 0" />
    <parent link="left_shoulder_yaw_link" />
    <child link="left_elbow_link" />
    <axis xyz="0 1 0" />
    <limit lower="-2.443" upper="1.571" effort="42" velocity="19.6" />
  </joint>
  <link name="left_wrist_yaw_link">
    <inertial>
      <origin xyz="-0.002420 0.000421 -0.014840" rpy="0 0 0" />
      <mass value="0.132906" />
      <inertia ixx="0.000145" ixy="0" ixz="0" iyy="0.000086" iyz="0.000001" izz="0.000142" />
    </inertial>
    <visual>
      <origin xyz="0 0 0" rpy="0 0 0" />
      <geometry>
        <mesh filename="package://HU_D04_description/meshes/HU_D04_01/left_wrist_yaw_link.STL" />
      </geometry>
      <material name="">
        <color rgba="0.75294 0.75294 0.75294 1" />
      </material>
    </visual>
    
  </link>
  <joint name="left_wrist_yaw_joint" type="revolute">
    <origin xyz="0 0.001 -0.1188" rpy="0 0 0" />
    <parent link="left_elbow_link" />
    <child link="left_wrist_yaw_link" />
    <axis xyz="0 0 1" />
    <limit lower="-2.356" upper="0.785" effort="19" velocity="13" />
  </joint>
  <link name="left_wrist_pitch_link">
    <inertial>
      <origin xyz="0.001436 0.001303 -0.032233" rpy="0 0 0" />
      <mass value="0.658602" />
      <inertia ixx="0.000952" ixy="0.000001" ixz="0.000028" iyy="0.000963" iyz="-0.000024" izz="0.000296" />
    </inertial>
    <visual>
      <origin xyz="0 0 0" rpy="0 0 0" />
      <geometry>
        <mesh filename="package://HU_D04_description/meshes/HU_D04_01/left_wrist_pitch_link.STL" />
      </geometry>
      <material name="">
        <color rgba="0.75294 0.75294 0.75294 1" />
      </material>
    </visual>
    
  </link>
  <joint name="left_wrist_pitch_joint" type="revolute">
    <origin xyz="0 0 -0.0342" rpy="0 0 0" />
    <parent link="left_wrist_yaw_link" />
    <child link="left_wrist_pitch_link" />
    <axis xyz="0 1 0" />
    <limit lower="-1.571" upper="1.571" effort="19" velocity="13" />
  </joint>
  <link name="left_wrist_roll_link">
    <inertial>
      <origin xyz="-0.00051 -8.9E-05 -0.029603" rpy="0 0 0" />
      <mass value="0.302626" />
      <inertia ixx="0.000231" ixy="0" ixz="0.000001" iyy="0.000313" iyz="0" izz="0.000308" />
    </inertial>
    <visual>
      <origin xyz="0 0 0" rpy="0 0 0" />
      <geometry>
        <mesh filename="package://HU_D04_description/meshes/HU_D04_01/left_wrist_roll_short_link.STL" />
      </geometry>
      <material name="">
        <color rgba="0.75294 0.75294 0.75294 1" />
      </material>
    </visual>
    
  </link>
  <joint name="left_wrist_roll_joint" type="revolute">
    <origin xyz="0 0 -0.065" rpy="0 0 0" />
    <parent link="left_wrist_pitch_link" />
    <child link="left_wrist_roll_link" />
    <axis xyz="1 0 0" />
    <limit lower="-1.571" upper="1.571" effort="19" velocity="13" />
  </joint>

  
  <joint name="left_hand_contact_joint" type="fixed">
    <origin xyz="0 0 -0.058" rpy="0 0 0" />
    <parent link="left_wrist_roll_link" />
    <child link="left_hand_contact" />
  </joint>
  <link name="left_hand_contact">
    <inertial>
      <origin xyz=".0 .0 .0" rpy="0 0 0" />
      <mass value="0.001" />
      <inertia ixx="0.0000001" ixy="0.0" ixz="0.0" iyy="0.0000001" iyz="0.0" izz="0.0000001" />
    </inertial>
    <visual>
      <origin xyz="0 0 0" rpy="0 0 0" />
      <geometry>
        <box size="0.01 0.01 0.01" />
      </geometry>
      <material name="">
        <color rgba="1 0 0 1" />
      </material>
    </visual>
  </link>

  
  <joint name="left_hand_manip_joint" type="fixed">
    <origin xyz="0 0 -0.058" rpy="0 1.5708 0" />
    <parent link="left_wrist_roll_link" />
    <child link="left_hand_manip" />
  </joint>
  <link name="left_hand_manip">
    <inertial>
      <origin xyz=".0 .0 .0" rpy="0 0 0" />
      <mass value="0.001" />
      <inertia ixx="0.0000001" ixy="0.0" ixz="0.0" iyy="0.0000001" iyz="0.0" izz="0.0000001" />
    </inertial>
    <visual>
      <origin xyz="0 0 0" rpy="0 0 0" />
      <geometry>
        <box size="0.01 0.01 0.01" />
      </geometry>
      <material name="">
        <color rgba="1 0 0 1" />
      </material>
    </visual>
  </link>

  <link name="right_shoulder_pitch_link">
    <inertial>
      <origin xyz="0.003151 -0.031104 -2.2E-05" rpy="0 0 0" />
      <mass value="0.244765" />
      <inertia ixx="0.000253" ixy="2.3E-05" ixz="0" iyy="0.000367" iyz="0" izz="0.000429" />
    </inertial>
    <visual>
      <origin xyz="0 0 0" rpy="0 0 0" />
      <geometry>
        <mesh filename="package://HU_D04_description/meshes/HU_D04_01/right_shoulder_pitch_link.STL" />
      </geometry>
      <material name="">
        <color rgba="0.75294 0.75294 0.75294 1" />
      </material>
    </visual>
    
  </link>
  <joint name="right_shoulder_pitch_joint" type="revolute">
    <origin xyz="0 -0.1589 0.2822" rpy="0 0 0" />
    <parent link="waist_pitch_link" />
    <child link="right_shoulder_pitch_link" />
    <axis xyz="0 1 0" />
    <limit lower="-2.792" upper="2.792" effort="42" velocity="19.6" />
  </joint>
  <link name="right_shoulder_roll_link">
    <inertial>
      <origin xyz="0.003553 8E-05 -0.046159" rpy="0 0 0" />
      <mass value="1.727406" />
      <inertia ixx="0.00488" ixy="2E-06" ixz="-0.000255" iyy="0.004864" iyz="1E-06" izz="0.001378" />
    </inertial>
    <visual>
      <origin xyz="0 0 0" rpy="0 0 0" />
      <geometry>
        <mesh filename="package://HU_D04_description/meshes/HU_D04_01/right_shoulder_roll_link.STL" />
      </geometry>
      <material name="">
        <color rgba="0.75294 0.75294 0.75294 1" />
      </material>
    </visual>
    
  </link>
  <joint name="right_shoulder_roll_joint" type="revolute">
    <origin xyz="0 -0.055 0" rpy="0 0 0" />
    <parent link="right_shoulder_pitch_link" />
    <child link="right_shoulder_roll_link" />
    <axis xyz="1 0 0" />
    <limit lower="-3.229" upper="0.087" effort="42" velocity="19.6" />
  </joint>
  <link name="right_shoulder_yaw_link">
    <inertial>
      <origin xyz="-0.009999 -0.003523 -0.06579" rpy="0 0 0" />
      <mass value="0.306436" />
      <inertia ixx="0.000871" ixy="9E-06" ixz="-1.9E-05" iyy="0.000736" iyz="-3.8E-05" izz="0.000405" />
    </inertial>
    <visual>
      <origin xyz="0 0 0" rpy="0 0 0" />
      <geometry>
        <mesh filename="package://HU_D04_description/meshes/HU_D04_01/right_shoulder_yaw_link.STL" />
      </geometry>
      <material name="">
        <color rgba="0.75294 0.75294 0.75294 1" />
      </material>
    </visual>
    
  <collision><origin xyz="0 0 -0.015" rpy="0 0 0" /><geometry><sphere radius="0.03" /></geometry></collision></link>
  <joint name="right_shoulder_yaw_joint" type="revolute">
    <origin xyz="0 0 -0.1306" rpy="0 0 0" />
    <parent link="right_shoulder_roll_link" />
    <child link="right_shoulder_yaw_link" />
    <axis xyz="0 0 1" />
    <limit lower="-1.571" upper="3.403" effort="42" velocity="19.6" />
  </joint>
  <link name="right_elbow_link">
    <inertial>
      <origin xyz="0.000057 -0.004497 -0.027441" rpy="0 0 0" />
      <mass value="1.275459" />
      <inertia ixx="0.002852" ixy="0.000003" ixz="0.000017" iyy="0.002876" iyz="0.000129" izz="0.000888" />
    </inertial>
    <visual>
      <origin xyz="0 0 0" rpy="0 0 0" />
      <geometry>
        <mesh filename="package://HU_D04_description/meshes/HU_D04_01/right_elbow_link.STL" />
      </geometry>
      <material name="">
        <color rgba="0.75294 0.75294 0.75294 1" />
      </material>
    </visual>
    
  <collision><origin xyz="0.05 0 -0.01" rpy="0 0 0" /><geometry><sphere radius="0.03" /></geometry></collision></link>
  <joint name="right_elbow_joint" type="revolute">
    <origin xyz="0 0 -0.1157" rpy="0 0 0" />
    <parent link="right_shoulder_yaw_link" />
    <child link="right_elbow_link" />
    <axis xyz="0 1 0" />
    <limit lower="-2.443" upper="1.571" effort="42" velocity="19.6" />
  </joint>
  <link name="right_wrist_yaw_link">
    <inertial>
      <origin xyz="-0.002420 -0.000421 -0.014840" rpy="0 0 0" />
      <mass value="0.132906" />
      <inertia ixx="0.000145" ixy="0" ixz="0" iyy="0.000086" iyz="-0.000001" izz="0.000142" />
    </inertial>
    <visual>
      <origin xyz="0 0 0" rpy="0 0 0" />
      <geometry>
        <mesh filename="package://HU_D04_description/meshes/HU_D04_01/right_wrist_yaw_link.STL" />
      </geometry>
      <material name="">
        <color rgba="0.75294 0.75294 0.75294 1" />
      </material>
    </visual>
    
  </link>
  <joint name="right_wrist_yaw_joint" type="revolute">
    <origin xyz="0 -0.001 -0.1188" rpy="0 0 0" />
    <parent link="right_elbow_link" />
    <child link="right_wrist_yaw_link" />
    <axis xyz="0 0 1" />
    <limit lower="-0.785" upper="2.356" effort="19" velocity="13" />
  </joint>
  <link name="right_wrist_pitch_link">
    <inertial>
      <origin xyz="0.001436 -0.001303 -0.032233" rpy="0 0 0" />
      <mass value="0.658602" />
      <inertia ixx="0.000952" ixy="-0.000001" ixz="0.000028" iyy="0.000963" iyz="0.000024" izz="0.000296" />
    </inertial>
    <visual>
      <origin xyz="0 0 0" rpy="0 0 0" />
      <geometry>
        <mesh filename="package://HU_D04_description/meshes/HU_D04_01/right_wrist_pitch_link.STL" />
      </geometry>
      <material name="">
        <color rgba="0.75294 0.75294 0.75294 1" />
      </material>
    </visual>
    
  </link>
  <joint name="right_wrist_pitch_joint" type="revolute">
    <origin xyz="0 0 -0.0342" rpy="0 0 0" />
    <parent link="right_wrist_yaw_link" />
    <child link="right_wrist_pitch_link" />
    <axis xyz="0 1 0" />
    <limit lower="-1.571" upper="1.571" effort="19" velocity="13" />
  </joint>
  <link name="right_wrist_roll_link">
    <inertial>
      <origin xyz="-0.000511 -8.9E-05 -0.029603" rpy="0 0 0" />
      <mass value="0.302626" />
      <inertia ixx="0.000231" ixy="0" ixz="0.000001" iyy="0.000313" iyz="0" izz="0.000308" />
    </inertial>
    <visual>
      <origin xyz="0 0 0" rpy="0 0 0" />
      <geometry>
        <mesh filename="package://HU_D04_description/meshes/HU_D04_01/right_wrist_roll_short_link.STL" />
      </geometry>
      <material name="">
        <color rgba="0.75294 0.75294 0.75294 1" />
      </material>
    </visual>
    
  </link>
  <joint name="right_wrist_roll_joint" type="revolute">
    <origin xyz="0 0 -0.065" rpy="0 0 0" />
    <parent link="right_wrist_pitch_link" />
    <child link="right_wrist_roll_link" />
    <axis xyz="1 0 0" />
    <limit lower="-1.571" upper="1.571" effort="19" velocity="13" />
  </joint>

  
  <joint name="right_hand_contact_joint" type="fixed">
    <origin xyz="0 0 -0.058" rpy="0 0 0" />
    <parent link="right_wrist_roll_link" />
    <child link="right_hand_contact" />
  </joint>
  <link name="right_hand_contact">
    <inertial>
      <origin xyz=".0 .0 .0" rpy="0 0 0" />
      <mass value="0.001" />
      <inertia ixx="0.0000001" ixy="0.0" ixz="0.0" iyy="0.0000001" iyz="0.0" izz="0.0000001" />
    </inertial>
    <visual>
      <origin xyz="0 0 0" rpy="0 0 0" />
      <geometry>
        <box size="0.01 0.01 0.01" />
      </geometry>
      <material name="">
        <color rgba="1 0 0 1" />
      </material>
    </visual>
  </link>

  
  <joint name="right_hand_manip_joint" type="fixed">
    <origin xyz="0 0 -0.058" rpy="0 1.5708 0" />
    <parent link="right_wrist_roll_link" />
    <child link="right_hand_manip" />
  </joint>
  <link name="right_hand_manip">
    <inertial>
      <origin xyz=".0 .0 .0" rpy="0 0 0" />
      <mass value="0.001" />
      <inertia ixx="0.0000001" ixy="0.0" ixz="0.0" iyy="0.0000001" iyz="0.0" izz="0.0000001" />
    </inertial>
    <visual>
      <origin xyz="0 0 0" rpy="0 0 0" />
      <geometry>
        <box size="0.01 0.01 0.01" />
      </geometry>
      <material name="">
        <color rgba="1 0 0 1" />
      </material>
    </visual>
  </link>
  
  <link name="head_yaw_link">
    <inertial>
      <origin xyz="-7E-05 0.002132 0.037884" rpy="0 0 0" />
      <mass value="0.35819" />
      <inertia ixx="0.000163" ixy="0" ixz="2E-06" iyy="0.000162" iyz="2E-06" izz="0.000146" />
    </inertial>
    <visual>
      <origin xyz="0 0 0" rpy="0 0 0" />
      <geometry>
        <mesh filename="package://HU_D04_description/meshes/HU_D04_01/neck_yaw_link.STL" />
      </geometry>
      <material name="">
        <color rgba="0.75294 0.75294 0.75294 1" />
      </material>
    </visual>
    
  </link>
  <joint name="head_yaw_joint" type="fixed">
    <origin xyz="-0.013 0 0.3882" rpy="0 0 0" />
    <parent link="waist_pitch_link" />
    <child link="head_yaw_link" />
    <axis xyz="0 0 1" />
    <limit lower="-0.785" upper="0.785" effort="19" velocity="13" />
  </joint>
  <link name="head_pitch_link">
    <inertial>
      <origin xyz="0.010255 -0.000319 0.069397" rpy="0 0 0" />
      <mass value="0.776041" />
      <inertia ixx="0.00265" ixy="-2E-06" ixz="0.000195" iyy="0.002337" iyz="0" izz="0.003495" />
    </inertial>
    <visual>
      <origin xyz="0 0 0" rpy="0 0 0" />
      <geometry>
        <mesh filename="package://HU_D04_description/meshes/HU_D04_01/neck_pitch_link.STL" />
      </geometry>
      <material name="">
        <color rgba="0.75294 0.75294 0.75294 1" />
      </material>
    </visual>
    
  </link>
  <joint name="head_pitch_joint" type="fixed">
    <origin xyz="0 0 0.0395" rpy="0 0 0" />
    <parent link="head_yaw_link" />
    <child link="head_pitch_link" />
    <axis xyz="0 1 0" />
    <limit lower="-0.524" upper="0.785" effort="19" velocity="13" />
  </joint>
  
  
  <link name="left_transition_link">
    <inertial>
      <origin xyz=".0 .0 .0" rpy="0 0 0" />
      <mass value="0.001" />
      <inertia ixx="0.0000001" ixy="0.0" ixz="0.0" iyy="0.0000001" iyz="0.0" izz="0.0000001" />
    </inertial>
    <visual>
      <origin xyz="0 0 0" rpy="0 0 0" />
      <geometry>
        <mesh filename="../meshes/HU_D04_01/hand_transition_link.STL" />
      </geometry>
      <material name="">
        <color rgba="1 1 1 1" />
      </material>
    </visual>
    
  </link>
  <joint name="left_transition_joint" type="fixed">
    <origin xyz="0.0 0.0 -0.062" rpy="0 0 0" />
    <parent link="left_wrist_roll_link" />
    <child link="left_transition_link" />
  </joint>
  <link name="left_palm_link">
    <inertial>
      <origin xyz="-0.00478670623240344 0.00141981128680179 0.0505239077176535" rpy="0 0 0" />
      <mass value="0.238" />
      <inertia ixx="2.2266510056133E-05" ixy="-2.6318583761649E-07" ixz="1.83638592892823E-07" iyy="1.55367220548952E-05" iyz="1.26586485241028E-06" izz="8.58669326263691E-06" />
    </inertial>
    <visual>
      <origin xyz="0 0 0" rpy="0 0 0" />
      <geometry>
        <mesh filename="package://HU_D04_description/meshes/HU_D04_01/left_base_link.STL" />
      </geometry>
      <material name="">
        <color rgba="1 1 1 1" />
      </material>
    </visual>
    
  </link>
  <joint name="left_palm_joint" type="fixed">
    <origin xyz="0 0 -0.08" rpy="3.14159 0 -1.578" />
    <parent link="left_wrist_roll_link" />
    <child link="left_palm_link" />
  </joint>
  <link name="right_transition_link">
    <inertial>
      <origin xyz=".0 .0 .0" rpy="0 0 0" />
      <mass value="0.001" />
      <inertia ixx="0.0000001" ixy="0.0" ixz="0.0" iyy="0.0000001" iyz="0.0" izz="0.0000001" />
    </inertial>
    <visual>
      <origin xyz="0 0 0" rpy="0 0 0" />
      <geometry>
        <mesh filename="../meshes/HU_D04_01/hand_transition_link.STL" />
      </geometry>
      <material name="">
        <color rgba="1 1 1 1" />
      </material>
    </visual>
    
  </link>
  <joint name="right_transition_joint" type="fixed">
    <origin xyz="0.0 0.0 -0.062" rpy="0 0 0" />
    <parent link="right_wrist_roll_link" />
    <child link="right_transition_link" />
  </joint>
  <link name="right_palm_link">
    <inertial>
      <origin xyz="-0.00477210157415217 -0.0014368255627066 0.0505186815078315" rpy="0 0 0" />
      <mass value="0.238" />
      <inertia ixx="2.22653147661907E-05" ixy="2.61914657870284E-07" ixz="1.85322175528149E-07" iyy="1.55386682543955E-05" iyz="-1.26178670079141E-06" izz="8.58493952480684E-06" />
    </inertial>
    <visual>
      <origin xyz="0 0 0" rpy="0 0 0" />
      <geometry>
        <mesh filename="package://HU_D04_description/meshes/HU_D04_01/right_base_link.STL" />
      </geometry>
      <material name="">
        <color rgba="1 1 1 1" />
      </material>
    </visual>
    
  </link>
  <joint name="right_palm_joint" type="fixed">
    <origin xyz="0 0 -0.08" rpy="3.14159 0 1.578" />
    <parent link="right_wrist_roll_link" />
    <child link="right_palm_link" />
  </joint>

  </robot>